<?xml version="1.0" ?>

<!--
    robco.xacro
    Provides macros for RobCo robot modules.
-->

<robot xmlns:xacro="http://www.ros.org/wiki/xacro">
    <xacro:property name="description_package" value="robco_description"/>
    <xacro:property name="default_prefix" value="robco"/>

    <xacro:macro name="robco_base_module" params="name mesh_filename tf_rpy tf_xyz next">
        <link name="${name}">
            <visual>
                <geometry>
                    <mesh filename="package://${description_package}/meshes/${mesh_filename}"/>
                </geometry>
                <material name="Gray">
                    <color rgba="0.9 0.9 0.9 1.0"/>
                </material>
            </visual>
        </link>

        <xacro:if value="${next != ''}">
            <joint name="${name}__${next}" type="fixed">
                <origin rpy="${tf_rpy}" xyz="${tf_xyz}"/>
                <parent link="${name}"/>
                <child link="${next}"/>
            </joint>
        </xacro:if>
    </xacro:macro>

    <xacro:macro name="robco_link_module" params="name mesh_filename tf_rpy tf_xyz next">
        <link name="${name}">
            <visual>
                <geometry>
                    <mesh filename="package://${description_package}/meshes/${mesh_filename}"/>
                </geometry>
                <material name="Gray">
                    <color rgba="0.9 0.9 0.9 1.0"/>
                </material>
            </visual>
        </link>

        <xacro:if value="${next != ''}">
            <joint name="${name}__${next}" type="fixed">
                <origin rpy="${tf_rpy}" xyz="${tf_xyz}"/>
                <parent link="${name}"/>
                <child link="${next}"/>
            </joint>
        </xacro:if>
     </xacro:macro>

    <xacro:macro name="robco_drive_module" params="name proximal_mesh_filename distal_mesh_filename proximal_tf_rpy proximal_tf_xyz distal_tf_rpy distal_tf_xyz lim_lower:=-4.7124 lim_upper:=4.7124 next">
        <!-- proximal link, calle ${name} to keep compatibility with next=... parameter -->
        <link name="${name}">
            <visual>
                <geometry>
                    <mesh filename="package://${description_package}/meshes/${proximal_mesh_filename}"/>
                </geometry>
                <material name="Gray">
                    <color rgba="0.9 0.9 0.9 1.0"/>
                </material>
            </visual>
        </link>
        
        <link name="${name}_shaft">
        </link>

        <link name="${name}_distal">
            <visual>
                <geometry>
                    <mesh filename="package://${description_package}/meshes/${distal_mesh_filename}"/>
                </geometry>
                <material name="Gray">
                    <color rgba="0.9 0.9 0.9 1.0"/>
                </material>
            </visual>
        </link>

        <joint name="${name}__${name}_shaft" type="fixed">
            <origin rpy="${proximal_tf_rpy}" xyz="${proximal_tf_xyz}"/>
            <parent link="${name}"/>
            <child link="${name}_shaft"/>
        </joint>
        
        <joint name="${name}_joint" type="revolute">
            <origin rpy="${distal_tf_rpy}" xyz="${distal_tf_xyz}"/>
            <axis xyz="0 0 1"/>
            <limit lower="${lim_lower}" upper="${lim_upper}" effort="0" velocity="0"/>
            <parent link="${name}_shaft"/>
            <child link="${name}_distal"/>
        </joint>

        <xacro:if value="${next != ''}">
            <joint name="${name}_distal__${next}" type="fixed">
                <parent link="${name}_distal"/>
                <child link="${next}"/>
            </joint>
        </xacro:if>
     </xacro:macro>

     <xacro:macro name="robco_end_effector" params="name mesh_filename tf_rpy tf_xyz">
        <link name="${name}">
            <visual>
                <geometry>
                    <mesh filename="package://${description_package}/meshes/${mesh_filename}"/>
                </geometry>
                <material name="Red">
                    <color rgba="1.0 0 0 1.0"/>
                </material>
            </visual>
        </link>
     </xacro:macro>

</robot>
